<?xml version="1.0" encoding="utf-8"?>
<!-- This URDF was automatically created by SolidWorks to URDF Exporter! Originally created by Stephen Brawner (brawner@gmail.com) 
     Commit Version: 1.6.0-4-g7f85cfe  Build Version: 1.6.7995.38578
     For more information, please see http://wiki.ros.org/sw_urdf_exporter -->
<robot
  name="fyp_robot_assem">
  <link
    name="base_link">
    <inertial>
      <origin
        xyz="-3.23835192863137E-19 6.60623793440799E-18 -1.24352714059445E-17"
        rpy="0 0 0" />
      <mass
        value="0.102173035023111" />
      <inertia
        ixx="0.000173628939136584"
        ixy="-4.13590306276514E-22"
        ixz="-2.61623768906717E-21"
        iyy="3.3437674543937E-05"
        iyz="-1.51579568114634E-20"
        izz="0.000190799013457422" />
    </inertial>
    <visual>
      <origin
        xyz="0 0 0"
        rpy="0 0 0" />
      <geometry>
        <mesh
          filename="package://fyp_robot_assem/meshes/base_link.STL" />
      </geometry>
      <material
        name="">
        <color
          rgba="0.792156862745098 0.819607843137255 0.933333333333333 1" />
      </material>
    </visual>
    <collision>
      <origin
        xyz="0 0 0"
        rpy="0 0 0" />
      <geometry>
        <mesh
          filename="package://fyp_robot_assem/meshes/base_link.STL" />
      </geometry>
    </collision>
  </link>
  <link
    name="link1">
    <inertial>
      <origin
        xyz="-0.0657997468109079 -0.0817969250537129 0.00833062304255519"
        rpy="0 0 0" />
      <mass
        value="0.234233661750754" />
      <inertia
        ixx="0.00106404720156785"
        ixy="-0.000783519338943125"
        ixz="-3.82085352502186E-05"
        iyy="0.000719862931747711"
        iyz="-4.7511460484771E-05"
        izz="0.00176266259552597" />
    </inertial>
    <visual>
      <origin
        xyz="0 0 0"
        rpy="0 0 0" />
      <geometry>
        <mesh
          filename="package://fyp_robot_assem/meshes/link1.STL" />
      </geometry>
      <material
        name="">
        <color
          rgba="0.792156862745098 0.819607843137255 0.933333333333333 1" />
      </material>
    </visual>
    <collision>
      <origin
        xyz="0 0 0"
        rpy="0 0 0" />
      <geometry>
        <mesh
          filename="package://fyp_robot_assem/meshes/link1.STL" />
      </geometry>
    </collision>
  </link>
  <joint
    name="joint1"
    type="continuous">
    <origin
      xyz="0.0175 0 0.0373735903262573"
      rpy="-1.5707963267949 0 -1.5707963267949" />
    <parent
      link="base_link" />
    <child
      link="link1" />
    <axis
      xyz="0 0 1" />
  </joint>
  <link
    name="link2">
    <inertial>
      <origin
        xyz="0.0789212285408834 -0.0303808902954582 0.00963591178429082"
        rpy="0 0 0" />
      <mass
        value="0.175905996218137" />
      <inertia
        ixx="0.00017227438622824"
        ixy="0.000365466989567327"
        ixz="3.99146063092048E-05"
        iyy="0.000981842005073185"
        iyz="-1.53529753077901E-05"
        izz="0.00113539435383725" />
    </inertial>
    <visual>
      <origin
        xyz="0 0 0"
        rpy="0 0 0" />
      <geometry>
        <mesh
          filename="package://fyp_robot_assem/meshes/link2.STL" />
      </geometry>
      <material
        name="">
        <color
          rgba="0.792156862745098 0.819607843137255 0.933333333333333 1" />
      </material>
    </visual>
    <collision>
      <origin
        xyz="0 0 0"
        rpy="0 0 0" />
      <geometry>
        <mesh
          filename="package://fyp_robot_assem/meshes/link2.STL" />
      </geometry>
    </collision>
  </link>
  <joint
    name="joint2"
    type="continuous">
    <origin
      xyz="-0.156657030121427 -0.194776017515082 0.0425"
      rpy="0 0 0" />
    <parent
      link="link1" />
    <child
      link="link2" />
    <axis
      xyz="0 0 1" />
  </joint>
</robot>