<?xml version="1.0" encoding="utf-8"?>
<!-- This URDF was automatically created by SolidWorks to URDF Exporter! Originally created by Stephen Brawner (brawner@gmail.com) 
     Commit Version: 1.6.0-4-g7f85cfe  Build Version: 1.6.7995.38578
     For more information, please see http://wiki.ros.org/sw_urdf_exporter -->
<robot
  name="fyp_robot_urdf">
  <link
    name="base_link">
    <inertial>
      <origin
        xyz="-7.12437424298901E-19 6.34716978011748E-18 -1.03627261716204E-17"
        rpy="0 0 0" />
      <mass
        value="0.102173035023111" />
      <inertia
        ixx="0.000173628939136584"
        ixy="-2.06795153138257E-22"
        ixz="-2.58069691561311E-21"
        iyy="3.3437674543937E-05"
        iyz="-1.5043764361097E-20"
        izz="0.000190799013457422" />
    </inertial>
    <visual>
      <origin
        xyz="0 0 0"
        rpy="0 0 0" />
      <geometry>
        <mesh
          filename="package://fyp_robot_urdf/meshes/base_link.STL" />
      </geometry>
      <material
        name="">
        <color
          rgba="0.792156862745098 0.819607843137255 0.933333333333333 1" />
      </material>
    </visual>
    <collision>
      <origin
        xyz="0 0 0"
        rpy="0 0 0" />
      <geometry>
        <mesh
          filename="package://fyp_robot_urdf/meshes/base_link.STL" />
      </geometry>
    </collision>
  </link>
  <link
    name="link1">
    <inertial>
      <origin
        xyz="-1.14851800061109E-07 -0.104996083572528 0.00833061727717447"
        rpy="0 0 0" />
      <mass
        value="0.234233603955478" />
      <inertia
        ixx="0.00169415003748716"
        ixy="-2.2013242422957E-10"
        ixz="2.51908289513765E-11"
        iyy="8.975920939518E-05"
        iyz="-6.09691536241392E-05"
        izz="0.00176266175853981" />
    </inertial>
    <visual>
      <origin
        xyz="0 0 0"
        rpy="0 0 0" />
      <geometry>
        <mesh
          filename="package://fyp_robot_urdf/meshes/link1.STL" />
      </geometry>
      <material
        name="">
        <color
          rgba="0.792156862745098 0.819607843137255 0.933333333333333 1" />
      </material>
    </visual>
    <collision>
      <origin
        xyz="0 0 0"
        rpy="0 0 0" />
      <geometry>
        <mesh
          filename="package://fyp_robot_urdf/meshes/link1.STL" />
      </geometry>
    </collision>
  </link>
  <joint
    name="joint1"
    type="revolute">
    <origin
      xyz="0.0175 0 0.03735"
      rpy="-1.5708 0 -1.5708" />
    <parent
      link="base_link" />
    <child
      link="link1" />
    <axis
      xyz="0 0 -1" />
    <limit
      lower="-1.5708"
      upper="1.5708"
      effort="8"
      velocity="30" />
  </joint>
  <link
    name="link2">
    <inertial>
      <origin
        xyz="-2.04143164574606E-07 -0.0845740345649362 0.00963593169000534"
        rpy="0 0 0" />
      <mass
        value="0.175905723230877" />
      <inertia
        ixx="0.00112242216598225"
        ixy="-1.6430030532982E-09"
        ixz="-5.36510996950036E-12"
        iyy="3.170063038781E-05"
        iyz="-4.27661808317735E-05"
        izz="0.00113540072351022" />
    </inertial>
    <visual>
      <origin
        xyz="0 0 0"
        rpy="0 0 0" />
      <geometry>
        <mesh
          filename="package://fyp_robot_urdf/meshes/link2.STL" />
      </geometry>
      <material
        name="">
        <color
          rgba="0.792156862745098 0.819607843137255 0.933333333333333 1" />
      </material>
    </visual>
    <collision>
      <origin
        xyz="0 0 0"
        rpy="0 0 0" />
      <geometry>
        <mesh
          filename="package://fyp_robot_urdf/meshes/link2.STL" />
      </geometry>
    </collision>
  </link>
  <joint
    name="joint2"
    type="revolute">
    <origin
      xyz="0 -0.25 0.0425"
      rpy="0 0 0" />
    <parent
      link="link1" />
    <child
      link="link2" />
    <axis
      xyz="0 0 -1" />
    <limit
      lower="-1.5708"
      upper="1.5708"
      effort="8"
      velocity="30" />
  </joint>
</robot>